Traceback (most recent call last):
  File "/Users/gy22808/opt/anaconda3/lib/python3.9/site-packages/jupyter_cache/executors/utils.py", line 51, in single_nb_execution
    executenb(
  File "/Users/gy22808/opt/anaconda3/lib/python3.9/site-packages/nbclient/client.py", line 1204, in execute
    return NotebookClient(nb=nb, resources=resources, km=km, **kwargs).execute()
  File "/Users/gy22808/opt/anaconda3/lib/python3.9/site-packages/nbclient/util.py", line 84, in wrapped
    return just_run(coro(*args, **kwargs))
  File "/Users/gy22808/opt/anaconda3/lib/python3.9/site-packages/nbclient/util.py", line 62, in just_run
    return loop.run_until_complete(coro)
  File "/Users/gy22808/opt/anaconda3/lib/python3.9/asyncio/base_events.py", line 647, in run_until_complete
    return future.result()
  File "/Users/gy22808/opt/anaconda3/lib/python3.9/site-packages/nbclient/client.py", line 663, in async_execute
    await self.async_execute_cell(
  File "/Users/gy22808/opt/anaconda3/lib/python3.9/site-packages/nbclient/client.py", line 965, in async_execute_cell
    await self._check_raise_for_error(cell, cell_index, exec_reply)
  File "/Users/gy22808/opt/anaconda3/lib/python3.9/site-packages/nbclient/client.py", line 862, in _check_raise_for_error
    raise CellExecutionError.from_cell_and_msg(cell, exec_reply_content)
nbclient.exceptions.CellExecutionError: An error occurred while executing the following cell:
------------------
## Option 1: use the package pyrosm to access the server and get the data
from pyrosm import OSM, get_data
bristol = get_data("bristol")
osm = OSM(bristol)
bristol_pois = osm.get_pois()
------------------

[0;31m---------------------------------------------------------------------------[0m
[0;31mModuleNotFoundError[0m                       Traceback (most recent call last)
Input [0;32mIn [6][0m, in [0;36m<cell line: 2>[0;34m()[0m
[1;32m      1[0m [38;5;66;03m## Option 1: use the package pyrosm to access the server and get the data[39;00m
[0;32m----> 2[0m [38;5;28;01mfrom[39;00m [38;5;21;01mpyrosm[39;00m [38;5;28;01mimport[39;00m OSM, get_data
[1;32m      3[0m bristol [38;5;241m=[39m get_data([38;5;124m"[39m[38;5;124mbristol[39m[38;5;124m"[39m)
[1;32m      4[0m osm [38;5;241m=[39m OSM(bristol)

File [0;32m~/opt/anaconda3/lib/python3.9/site-packages/pyrosm/__init__.py:2[0m, in [0;36m<module>[0;34m[0m
[1;32m      1[0m [38;5;28;01mfrom[39;00m [38;5;21;01mpyrosm[39;00m[38;5;21;01m.[39;00m[38;5;21;01mdata[39;00m [38;5;28;01mimport[39;00m get_data, get_path  [38;5;66;03m# drop get_path in the future[39;00m
[0;32m----> 2[0m [38;5;28;01mfrom[39;00m [38;5;21;01mpyrosm[39;00m[38;5;21;01m.[39;00m[38;5;21;01mpyrosm[39;00m [38;5;28;01mimport[39;00m OSM

File [0;32m~/opt/anaconda3/lib/python3.9/site-packages/pyrosm/pyrosm.py:5[0m, in [0;36m<module>[0;34m[0m
[1;32m      3[0m [38;5;28;01mfrom[39;00m [38;5;21;01mpyrosm[39;00m[38;5;21;01m.[39;00m[38;5;21;01mpbfreader[39;00m [38;5;28;01mimport[39;00m parse_osm_data
[1;32m      4[0m [38;5;28;01mfrom[39;00m [38;5;21;01mpyrosm[39;00m[38;5;21;01m.[39;00m[38;5;21;01m_arrays[39;00m [38;5;28;01mimport[39;00m concatenate_dicts_of_arrays
[0;32m----> 5[0m [38;5;28;01mfrom[39;00m [38;5;21;01mpyrosm[39;00m[38;5;21;01m.[39;00m[38;5;21;01mgeometry[39;00m [38;5;28;01mimport[39;00m create_node_coordinates_lookup
[1;32m      6[0m [38;5;28;01mfrom[39;00m [38;5;21;01mpyrosm[39;00m[38;5;21;01m.[39;00m[38;5;21;01mframes[39;00m [38;5;28;01mimport[39;00m create_nodes_gdf
[1;32m      7[0m [38;5;28;01mfrom[39;00m [38;5;21;01mpyrosm[39;00m[38;5;21;01m.[39;00m[38;5;21;01mutils[39;00m [38;5;28;01mimport[39;00m (
[1;32m      8[0m     validate_custom_filter,
[1;32m      9[0m     validate_osm_keys,
[0;32m   (...)[0m
[1;32m     16[0m     get_bounding_box,
[1;32m     17[0m )

File [0;32m~/opt/anaconda3/lib/python3.9/site-packages/pyrosm/geometry.pyx:2[0m, in [0;36minit pyrosm.geometry[0;34m()[0m

[0;31mModuleNotFoundError[0m: No module named 'pygeos'
ModuleNotFoundError: No module named 'pygeos'

